<sdf version='1.6'>
  <world name='default'>
    <model name='ground_plane'>
      <static>1</static>
      <link name='link'>
        <collision name='collision'>
          <geometry>
            <plane>
              <normal>0 0 1</normal>
              <size>100 100</size>
            </plane>
          </geometry>
          <surface>
            <friction>
              <ode>
                <mu>100</mu>
                <mu2>50</mu2>
              </ode>
              <torsional>
                <ode/>
              </torsional>
            </friction>
            <contact>
              <ode/>
            </contact>
            <bounce/>
          </surface>
          <max_contacts>10</max_contacts>
        </collision>
        <visual name='visual'>
          <cast_shadows>0</cast_shadows>
          <geometry>
            <plane>
              <normal>0 0 1</normal>
              <size>100 100</size>
            </plane>
          </geometry>
          <material>
            <script>
              <uri>file://media/materials/scripts/gazebo.material</uri>
              <name>Gazebo/Grey</name>
            </script>
          </material>
        </visual>
        <self_collide>0</self_collide>
        <kinematic>0</kinematic>
        <gravity>1</gravity>
      </link>
    </model>
    <light name='sun' type='directional'>
      <cast_shadows>1</cast_shadows>
      <pose frame=''>0 0 10 0 -0 0</pose>
      <diffuse>0.8 0.8 0.8 1</diffuse>
      <specular>0.1 0.1 0.1 1</specular>
      <attenuation>
        <range>1000</range>
        <constant>0.9</constant>
        <linear>0.01</linear>
        <quadratic>0.001</quadratic>
      </attenuation>
      <direction>-0.5 0.5 -1</direction>
    </light>
    <physics name='default_physics' default='0' type='ode'>
      <real_time_update_rate>1000</real_time_update_rate>
      <max_step_size>0.001</max_step_size>
      <real_time_factor>1</real_time_factor>
    </physics>
    <gravity>0 0 -9.81</gravity>
    <gui fullscreen='0'>
      <camera name='user_camera'>
        <pose frame=''>0.437796 0.126745 4.30938 -0.001175 1.53355 3.14035</pose>
        <view_controller>orbit</view_controller>
        <projection_type>perspective</projection_type>
      </camera>
    </gui>
    <magnetic_field>6e-06 2.3e-05 -4.2e-05</magnetic_field>
    <atmosphere type='adiabatic'/>
    <scene>
      <ambient>0.4 0.4 0.4 1</ambient>
      <background>0.7 0.7 0.7 1</background>
      <shadows>1</shadows>
    </scene>
    <spherical_coordinates>
      <surface_model>EARTH_WGS84</surface_model>
      <latitude_deg>0</latitude_deg>
      <longitude_deg>0</longitude_deg>
      <elevation>0</elevation>
      <heading_deg>0</heading_deg>
    </spherical_coordinates>
    <model name='sawyer'>
      <link name='base'>
        <pose frame=''>0 0 0 0 -0 0</pose>
        <inertial>
          <pose frame=''>-2.1e-05 -1e-06 -0.481414 0 -0 0</pose>
          <mass>62.9327</mass>
          <inertia>
            <ixx>5.70994</ixx>
            <ixy>0.000992111</ixy>
            <ixz>0.802702</ixz>
            <iyy>6.73327</iyy>
            <iyz>0.0011007</iyz>
            <izz>4.96932</izz>
          </inertia>
        </inertial>
        <collision name='base_fixed_joint_lump__controller_box_collision'>
          <pose frame=''>-0.325 0 -0.38 0 -0 0</pose>
          <geometry>
            <box>
              <size>0.22 0.4 0.53</size>
            </box>
          </geometry>
          <max_contacts>10</max_contacts>
          <surface>
            <contact>
              <ode/>
            </contact>
            <bounce/>
            <friction>
              <torsional>
                <ode/>
              </torsional>
              <ode/>
            </friction>
          </surface>
        </collision>
        <collision name='base_fixed_joint_lump__pedestal_feet_collision_1'>
          <pose frame=''>-0.1225 0 -0.758 0 -0 0</pose>
          <geometry>
            <box>
              <size>0.77 0.7 0.31</size>
            </box>
          </geometry>
          <max_contacts>10</max_contacts>
          <surface>
            <contact>
              <ode/>
            </contact>
            <bounce/>
            <friction>
              <torsional>
                <ode/>
              </torsional>
              <ode/>
            </friction>
          </surface>
        </collision>
        <collision name='base_fixed_joint_lump__pedestal_collision_2'>
          <pose frame=''>-0.02 0 -0.29 0 -0 0</pose>
          <geometry>
            <cylinder>
              <length>0.62</length>
              <radius>0.18</radius>
            </cylinder>
          </geometry>
          <surface>
            <contact>
              <ode/>
            </contact>
            <friction>
              <ode/>
              <torsional>
                <ode/>
              </torsional>
            </friction>
            <bounce/>
          </surface>
          <max_contacts>10</max_contacts>
        </collision>
        <collision name='base_fixed_joint_lump__right_arm_base_link_collision_3'>
          <pose frame=''>0 0 0.12 0 -0 0</pose>
          <geometry>
            <cylinder>
              <length>0.24</length>
              <radius>0.08</radius>
            </cylinder>
          </geometry>
          <max_contacts>10</max_contacts>
          <surface>
            <contact>
              <ode/>
            </contact>
            <bounce/>
            <friction>
              <torsional>
                <ode/>
              </torsional>
              <ode/>
            </friction>
          </surface>
        </collision>
        <visual name='base_fixed_joint_lump__pedestal_visual'>
          <pose frame=''>0.26 0.345 -0.91488 1.5708 0 -1.5708</pose>
          <geometry>
            <mesh>
              <scale>1 1 1</scale>
              <uri>/home/user/ros_ws/src/sawyer_robot/sawyer_description/meshes/sawyer_pv/pedestal.DAE</uri>
            </mesh>
          </geometry>
          <material>
            <script>
              <name>Gazebo/FlatBlack</name>
              <uri>file://media/materials/scripts/gazebo.material</uri>
            </script>
          </material>
        </visual>
        <visual name='base_fixed_joint_lump__right_arm_base_link_visual_1'>
          <pose frame=''>0 0 0 0 -0 0</pose>
          <geometry>
            <mesh>
              <scale>1 1 1</scale>
              <uri>/home/user/ros_ws/src/sawyer_robot/sawyer_description/meshes/sawyer_pv/base.DAE</uri>
            </mesh>
          </geometry>
        </visual>
        <visual name='base_fixed_joint_lump__torso_visual_2'>
          <pose frame=''>0 0 0 0 -0 0</pose>
          <geometry>
            <box>
              <size>0.001 0.001 0.001</size>
            </box>
          </geometry>
          <material>
            <script>
              <uri>__default__</uri>
              <name>__default__</name>
            </script>
          </material>
        </visual>
        <velocity_decay/>
        <gravity>1</gravity>
        <velocity_decay/>
        <self_collide>0</self_collide>
        <self_collide>1</self_collide>
        <kinematic>0</kinematic>
      </link>
      <joint name='fixed' type='revolute'>
        <child>base</child>
        <parent>world</parent>
        <axis>
          <limit>
            <lower>0</lower>
            <upper>0</upper>
          </limit>
          <dynamics>
            <damping>0</damping>
            <friction>0</friction>
            <spring_reference>0</spring_reference>
            <spring_stiffness>0</spring_stiffness>
          </dynamics>
          <use_parent_model_frame>1</use_parent_model_frame>
          <xyz>0 0 1</xyz>
        </axis>
      </joint>
      <link name='right_l0'>
        <pose frame=''>0 0 0.08 0 -0 0</pose>
        <inertial>
          <pose frame=''>0.024366 0.010969 0.14363 0 -0 0</pose>
          <mass>5.3213</mass>
          <inertia>
            <ixx>0.053314</ixx>
            <ixy>0.0047093</ixy>
            <ixz>0.011734</ixz>
            <iyy>0.057902</iyy>
            <iyz>0.0080179</iyz>
            <izz>0.023659</izz>
          </inertia>
        </inertial>
        <collision name='right_l0_collision'>
          <pose frame=''>0.08 0 0.23 0 -0 0</pose>
          <geometry>
            <sphere>
              <radius>0.07</radius>
            </sphere>
          </geometry>
          <max_contacts>10</max_contacts>
          <surface>
            <contact>
              <ode/>
            </contact>
            <bounce/>
            <friction>
              <torsional>
                <ode/>
              </torsional>
              <ode/>
            </friction>
          </surface>
        </collision>
        <visual name='right_l0_visual'>
          <pose frame=''>0 0 0 0 -0 0</pose>
          <geometry>
            <mesh>
              <scale>1 1 1</scale>
              <uri>/home/user/ros_ws/src/sawyer_robot/sawyer_description/meshes/sawyer_mp3/l0.DAE</uri>
            </mesh>
          </geometry>
        </visual>
        <self_collide>0</self_collide>
        <kinematic>0</kinematic>
        <gravity>1</gravity>
      </link>
      <joint name='right_j0' type='revolute'>
        <child>right_l0</child>
        <parent>base</parent>
        <axis>
          <xyz>0 0 1</xyz>
          <limit>
            <lower>-3.0503</lower>
            <upper>3.0503</upper>
            <effort>80</effort>
            <velocity>1.74</velocity>
          </limit>
          <dynamics>
            <damping>10</damping>
            <friction>5</friction>
            <spring_reference>0</spring_reference>
            <spring_stiffness>0</spring_stiffness>
          </dynamics>
          <use_parent_model_frame>1</use_parent_model_frame>
        </axis>
        <physics>
          <provide_feedback>1</provide_feedback>
          <ode>
            <provide_feedback>1</provide_feedback>
            <implicit_spring_damper>1</implicit_spring_damper>
            <cfm_damping>1</cfm_damping>
            <limit>
              <cfm>0</cfm>
              <erp>0.2</erp>
            </limit>
          </ode>
        </physics>
      </joint>
      <link name='head'>
        <pose frame=''>0 0 0.3765 0 -0 0</pose>
        <inertial>
          <pose frame=''>0.005321 -2.7e-05 0.1021 0 -0 0</pose>
          <mass>1.5795</mass>
          <inertia>
            <ixx>0.011833</ixx>
            <ixy>-4.4669e-06</ixy>
            <ixz>4.9425e-05</ixz>
            <iyy>0.0082709</iyy>
            <iyz>4.2124e-07</iyz>
            <izz>0.0049661</izz>
          </inertia>
        </inertial>
        <collision name='head_collision'>
          <pose frame=''>0 0 0.08 0 -0 0</pose>
          <geometry>
            <sphere>
              <radius>0.18</radius>
            </sphere>
          </geometry>
          <max_contacts>10</max_contacts>
          <surface>
            <contact>
              <ode/>
            </contact>
            <bounce/>
            <friction>
              <torsional>
                <ode/>
              </torsional>
              <ode/>
            </friction>
          </surface>
        </collision>
        <collision name='head_fixed_joint_lump__screen_collision_1'>
          <pose frame=''>0.03 0 0.105 1.5708 -0 1.5708</pose>
          <geometry>
            <sphere>
              <radius>0.001</radius>
            </sphere>
          </geometry>
          <surface>
            <contact>
              <ode/>
            </contact>
            <friction>
              <ode/>
              <torsional>
                <ode/>
              </torsional>
            </friction>
            <bounce/>
          </surface>
          <max_contacts>10</max_contacts>
        </collision>
        <visual name='head_visual'>
          <pose frame=''>0 0 0 0 -0 0</pose>
          <geometry>
            <mesh>
              <scale>1 1 1</scale>
              <uri>/home/user/ros_ws/src/sawyer_robot/sawyer_description/meshes/sawyer_pv/head.DAE</uri>
            </mesh>
          </geometry>
        </visual>
        <visual name='head_fixed_joint_lump__screen_visual_1'>
          <pose frame=''>0.03 0 0.105 1.5708 -0 1.5708</pose>
          <geometry>
            <box>
              <size>0.24 0.14 0.002</size>
            </box>
          </geometry>
          <plugin name='screen_video_controller' filename='libgazebo_ros_video.so'>
            <height>600</height>
            <width>1024</width>
            <topicName>/robot/head_display</topicName>
            <robotNamespace>/robot</robotNamespace>
          </plugin>
          <material>
            <script>
              <uri>__default__</uri>
              <name>__default__</name>
            </script>
          </material>
        </visual>
        <velocity_decay/>
        <gravity>1</gravity>
        <velocity_decay/>
        <self_collide>0</self_collide>
        <sensor name='head_camera' type='camera'>
          <update_rate>10</update_rate>
          <camera name='head_camera'>
            <horizontal_fov>2.00787</horizontal_fov>
            <image>
              <width>1280</width>
              <height>800</height>
              <format>R8G8B8</format>
            </image>
            <clip>
              <near>0.1</near>
              <far>50</far>
            </clip>
          </camera>
          <plugin name='camera_controller' filename='libgazebo_ros_camera.so'>
            <alwaysOn>true</alwaysOn>
            <updateRate>10</updateRate>
            <cameraName>head_camera</cameraName>
            <imageTopicName>/io/internal_camera/head_camera/image_raw</imageTopicName>
            <cameraInfoTopicName>/io/internal_camera/head_camera/camera_info</cameraInfoTopicName>
            <frameName>head_camera</frameName>
            <focalLength>407.391526</focalLength>
            <robotNamespace>/</robotNamespace>
          </plugin>
          <pose frame=''>0.022803 0 0.216572 0 0.558504 0</pose>
        </sensor>
        <kinematic>0</kinematic>
      </link>
      <joint name='head_pan' type='revolute'>
        <child>head</child>
        <parent>right_l0</parent>
        <axis>
          <xyz>0 0 1</xyz>
          <limit>
            <lower>-5.0952</lower>
            <upper>0.9064</upper>
            <effort>8</effort>
            <velocity>1.8</velocity>
          </limit>
          <dynamics>
            <damping>1</damping>
            <friction>0.5</friction>
            <spring_reference>0</spring_reference>
            <spring_stiffness>0</spring_stiffness>
          </dynamics>
          <use_parent_model_frame>1</use_parent_model_frame>
        </axis>
        <physics>
          <provide_feedback>1</provide_feedback>
          <ode>
            <provide_feedback>1</provide_feedback>
            <implicit_spring_damper>1</implicit_spring_damper>
            <cfm_damping>1</cfm_damping>
            <limit>
              <cfm>0</cfm>
              <erp>0.2</erp>
            </limit>
          </ode>
        </physics>
      </joint>
      <link name='right_l1'>
        <pose frame=''>0.081 0.05 0.317 1.57078 1.57079 3.14158</pose>
        <inertial>
          <pose frame=''>-0.003085 -0.026811 0.092521 0 -0 0</pose>
          <mass>4.505</mass>
          <inertia>
            <ixx>0.022398</ixx>
            <ixy>-0.00023986</ixy>
            <ixz>-0.00029362</ixz>
            <iyy>0.014613</iyy>
            <iyz>-0.0060875</iyz>
            <izz>0.017295</izz>
          </inertia>
        </inertial>
        <collision name='right_l1_collision'>
          <pose frame=''>0 0 0.1225 0 -0 0</pose>
          <geometry>
            <sphere>
              <radius>0.07</radius>
            </sphere>
          </geometry>
          <max_contacts>10</max_contacts>
          <surface>
            <contact>
              <ode/>
            </contact>
            <bounce/>
            <friction>
              <torsional>
                <ode/>
              </torsional>
              <ode/>
            </friction>
          </surface>
        </collision>
        <collision name='right_l1_2_collision_1'>
          <pose frame=''>0 0 0.035 0 -0 0</pose>
          <geometry>
            <cylinder>
              <length>0.14</length>
              <radius>0.07</radius>
            </cylinder>
          </geometry>
          <max_contacts>10</max_contacts>
          <surface>
            <contact>
              <ode/>
            </contact>
            <bounce/>
            <friction>
              <torsional>
                <ode/>
              </torsional>
              <ode/>
            </friction>
          </surface>
        </collision>
        <visual name='right_l1_visual'>
          <pose frame=''>0 0 0 0 -0 0</pose>
          <geometry>
            <mesh>
              <scale>1 1 1</scale>
              <uri>/home/user/ros_ws/src/sawyer_robot/sawyer_description/meshes/sawyer_mp3/l1.DAE</uri>
            </mesh>
          </geometry>
        </visual>
        <self_collide>0</self_collide>
        <kinematic>0</kinematic>
        <gravity>1</gravity>
      </link>
      <joint name='right_j1' type='revolute'>
        <child>right_l1</child>
        <parent>right_l0</parent>
        <axis>
          <xyz>0 1 0</xyz>
          <limit>
            <lower>-3.8095</lower>
            <upper>2.2736</upper>
            <effort>80</effort>
            <velocity>1.328</velocity>
          </limit>
          <dynamics>
            <damping>5</damping>
            <friction>2</friction>
            <spring_reference>0</spring_reference>
            <spring_stiffness>0</spring_stiffness>
          </dynamics>
          <use_parent_model_frame>1</use_parent_model_frame>
        </axis>
        <physics>
          <provide_feedback>1</provide_feedback>
          <ode>
            <provide_feedback>1</provide_feedback>
            <implicit_spring_damper>1</implicit_spring_damper>
            <cfm_damping>1</cfm_damping>
            <limit>
              <cfm>0</cfm>
              <erp>0.2</erp>
            </limit>
          </ode>
        </physics>
      </joint>
      <link name='right_l2'>
        <pose frame=''>0.221 0.1925 0.317 3.14158 1.57079 3.14158</pose>
        <inertial>
          <pose frame=''>-0.00016 -0.014967 0.13582 0 -0 0</pose>
          <mass>1.745</mass>
          <inertia>
            <ixx>0.025506</ixx>
            <ixy>4.4101e-06</ixy>
            <ixz>1.4955e-05</ixz>
            <iyy>0.0253</iyy>
            <iyz>-0.0033204</iyz>
            <izz>0.0034179</izz>
          </inertia>
        </inertial>
        <collision name='right_l2_collision'>
          <pose frame=''>0 0 0.08 0 -0 0</pose>
          <geometry>
            <cylinder>
              <length>0.34</length>
              <radius>0.06</radius>
            </cylinder>
          </geometry>
          <max_contacts>10</max_contacts>
          <surface>
            <contact>
              <ode/>
            </contact>
            <bounce/>
            <friction>
              <torsional>
                <ode/>
              </torsional>
              <ode/>
            </friction>
          </surface>
        </collision>
        <collision name='right_l2_2_collision_1'>
          <pose frame=''>0 0 0.26 0 -0 0</pose>
          <geometry>
            <sphere>
              <radius>0.06</radius>
            </sphere>
          </geometry>
          <max_contacts>10</max_contacts>
          <surface>
            <contact>
              <ode/>
            </contact>
            <bounce/>
            <friction>
              <torsional>
                <ode/>
              </torsional>
              <ode/>
            </friction>
          </surface>
        </collision>
        <visual name='right_l2_visual'>
          <pose frame=''>0 0 0 0 -0 0</pose>
          <geometry>
            <mesh>
              <scale>1 1 1</scale>
              <uri>/home/user/ros_ws/src/sawyer_robot/sawyer_description/meshes/sawyer_pv/l2.DAE</uri>
            </mesh>
          </geometry>
        </visual>
        <self_collide>0</self_collide>
        <kinematic>0</kinematic>
        <gravity>1</gravity>
      </link>
      <joint name='right_j2' type='revolute'>
        <child>right_l2</child>
        <parent>right_l1</parent>
        <axis>
          <xyz>1 0 0</xyz>
          <limit>
            <lower>-3.0426</lower>
            <upper>3.0426</upper>
            <effort>40</effort>
            <velocity>1.957</velocity>
          </limit>
          <dynamics>
            <damping>5</damping>
            <friction>2</friction>
            <spring_reference>0</spring_reference>
            <spring_stiffness>0</spring_stiffness>
          </dynamics>
          <use_parent_model_frame>1</use_parent_model_frame>
        </axis>
        <physics>
          <provide_feedback>1</provide_feedback>
          <ode>
            <provide_feedback>1</provide_feedback>
            <implicit_spring_damper>1</implicit_spring_damper>
            <cfm_damping>1</cfm_damping>
            <limit>
              <cfm>0</cfm>
              <erp>0.2</erp>
            </limit>
          </ode>
        </physics>
      </joint>
      <link name='right_l3'>
        <pose frame=''>0.481 0.1505 0.317 1.57078 1.57079 3.14158</pose>
        <inertial>
          <pose frame=''>-0.004814 -0.0281 -0.084154 0 -0 0</pose>
          <mass>2.5097</mass>
          <inertia>
            <ixx>0.01016</ixx>
            <ixy>-9.7452e-06</ixy>
            <ixz>0.00026624</ixz>
            <iyy>0.0065685</iyy>
            <iyz>0.0030316</iyz>
            <izz>0.0069078</izz>
          </inertia>
        </inertial>
        <collision name='right_l3_collision'>
          <pose frame=''>0 -0.01 -0.12 0 -0 0</pose>
          <geometry>
            <sphere>
              <radius>0.06</radius>
            </sphere>
          </geometry>
          <max_contacts>10</max_contacts>
          <surface>
            <contact>
              <ode/>
            </contact>
            <bounce/>
            <friction>
              <torsional>
                <ode/>
              </torsional>
              <ode/>
            </friction>
          </surface>
        </collision>
        <visual name='right_l3_visual'>
          <pose frame=''>0 0 0 0 -0 0</pose>
          <geometry>
            <mesh>
              <scale>1 1 1</scale>
              <uri>/home/user/ros_ws/src/sawyer_robot/sawyer_description/meshes/sawyer_pv/l3.DAE</uri>
            </mesh>
          </geometry>
        </visual>
        <self_collide>0</self_collide>
        <kinematic>0</kinematic>
        <gravity>1</gravity>
      </link>
      <joint name='right_j3' type='revolute'>
        <child>right_l3</child>
        <parent>right_l2</parent>
        <axis>
          <xyz>0 1 0</xyz>
          <limit>
            <lower>-3.0439</lower>
            <upper>3.0439</upper>
            <effort>40</effort>
            <velocity>1.957</velocity>
          </limit>
          <dynamics>
            <damping>1</damping>
            <friction>0.5</friction>
            <spring_reference>0</spring_reference>
            <spring_stiffness>0</spring_stiffness>
          </dynamics>
          <use_parent_model_frame>1</use_parent_model_frame>
        </axis>
        <physics>
          <provide_feedback>1</provide_feedback>
          <ode>
            <provide_feedback>1</provide_feedback>
            <implicit_spring_damper>1</implicit_spring_damper>
            <cfm_damping>1</cfm_damping>
            <limit>
              <cfm>0</cfm>
              <erp>0.2</erp>
            </limit>
          </ode>
        </physics>
      </joint>
      <link name='right_l4'>
        <pose frame=''>0.606 0.024 0.317 3.14158 1.57079 3.14158</pose>
        <inertial>
          <pose frame=''>-0.001884 0.0069 0.1341 0 -0 0</pose>
          <mass>1.1136</mass>
          <inertia>
            <ixx>0.013557</ixx>
            <ixy>1.8109e-05</ixy>
            <ixz>0.00013523</ixz>
            <iyy>0.013555</iyy>
            <iyz>0.0010561</iyz>
            <izz>0.0013658</izz>
          </inertia>
        </inertial>
        <collision name='right_l4_collision'>
          <pose frame=''>0 0 0.11 0 -0 0</pose>
          <geometry>
            <cylinder>
              <length>0.3</length>
              <radius>0.045</radius>
            </cylinder>
          </geometry>
          <max_contacts>10</max_contacts>
          <surface>
            <contact>
              <ode/>
            </contact>
            <bounce/>
            <friction>
              <torsional>
                <ode/>
              </torsional>
              <ode/>
            </friction>
          </surface>
        </collision>
        <collision name='right_l4_2_collision_1'>
          <pose frame=''>0 0.01 0.26 0 -0 0</pose>
          <geometry>
            <sphere>
              <radius>0.06</radius>
            </sphere>
          </geometry>
          <max_contacts>10</max_contacts>
          <surface>
            <contact>
              <ode/>
            </contact>
            <bounce/>
            <friction>
              <torsional>
                <ode/>
              </torsional>
              <ode/>
            </friction>
          </surface>
        </collision>
        <visual name='right_l4_visual'>
          <pose frame=''>0 0 0 0 -0 0</pose>
          <geometry>
            <mesh>
              <scale>1 1 1</scale>
              <uri>/home/user/ros_ws/src/sawyer_robot/sawyer_description/meshes/sawyer_pv/l4.DAE</uri>
            </mesh>
          </geometry>
        </visual>
        <self_collide>0</self_collide>
        <kinematic>0</kinematic>
        <gravity>1</gravity>
      </link>
      <joint name='right_j4' type='revolute'>
        <child>right_l4</child>
        <parent>right_l3</parent>
        <axis>
          <xyz>1 0 0</xyz>
          <limit>
            <lower>-2.9761</lower>
            <upper>2.9761</upper>
            <effort>9</effort>
            <velocity>3.485</velocity>
          </limit>
          <dynamics>
            <damping>2</damping>
            <friction>1</friction>
            <spring_reference>0</spring_reference>
            <spring_stiffness>0</spring_stiffness>
          </dynamics>
          <use_parent_model_frame>1</use_parent_model_frame>
        </axis>
        <physics>
          <provide_feedback>1</provide_feedback>
          <ode>
            <provide_feedback>1</provide_feedback>
            <implicit_spring_damper>1</implicit_spring_damper>
            <cfm_damping>1</cfm_damping>
            <limit>
              <cfm>0</cfm>
              <erp>0.2</erp>
            </limit>
          </ode>
        </physics>
      </joint>
      <link name='right_l5'>
        <pose frame=''>0.881 0.055 0.317 1.57078 1.57079 3.14158</pose>
        <inertial>
          <pose frame=''>0.006113 -0.023697 0.076416 0 -0 0</pose>
          <mass>1.5625</mass>
          <inertia>
            <ixx>0.0047328</ixx>
            <ixy>0.00011526</ixy>
            <ixz>4.6269e-05</ixz>
            <iyy>0.0029676</iyy>
            <iyz>-0.0011557</iyz>
            <izz>0.0031762</izz>
          </inertia>
        </inertial>
        <collision name='right_l5_collision'>
          <pose frame=''>0 0 0.1 0 -0 0</pose>
          <geometry>
            <sphere>
              <radius>0.06</radius>
            </sphere>
          </geometry>
          <max_contacts>10</max_contacts>
          <surface>
            <contact>
              <ode/>
            </contact>
            <bounce/>
            <friction>
              <torsional>
                <ode/>
              </torsional>
              <ode/>
            </friction>
          </surface>
        </collision>
        <visual name='right_l5_visual'>
          <pose frame=''>0 0 0 0 -0 0</pose>
          <geometry>
            <mesh>
              <scale>1 1 1</scale>
              <uri>/home/user/ros_ws/src/sawyer_robot/sawyer_description/meshes/sawyer_pv/l5.DAE</uri>
            </mesh>
          </geometry>
        </visual>
        <gravity>1</gravity>
        <velocity_decay/>
        <self_collide>0</self_collide>
        <sensor name='right_hand_camera' type='camera'>
          <update_rate>10</update_rate>
          <camera name='right_hand_camera'>
            <horizontal_fov>1.09929</horizontal_fov>
            <image>
              <width>752</width>
              <height>480</height>
              <format>L8</format>
            </image>
            <clip>
              <near>0.02</near>
              <far>10</far>
            </clip>
          </camera>
          <plugin name='camera_controller' filename='libgazebo_ros_camera.so'>
            <alwaysOn>true</alwaysOn>
            <updateRate>10.0</updateRate>
            <cameraName>right_hand_camera</cameraName>
            <imageTopicName>/io/internal_camera/right_hand_camera/image_raw</imageTopicName>
            <cameraInfoTopicName>/io/internal_camera/right_hand_camera/camera_info</cameraInfoTopicName>
            <frameName>right_hand_camera</frameName>
            <focalLength>613.760435</focalLength>
            <robotNamespace>/</robotNamespace>
          </plugin>
          <pose frame=''>0.039552 -0.033 0.0695 1.5708 -0 0</pose>
        </sensor>
        <kinematic>0</kinematic>
      </link>
      <joint name='right_j5' type='revolute'>
        <child>right_l5</child>
        <parent>right_l4</parent>
        <axis>
          <xyz>0 1 0</xyz>
          <limit>
            <lower>-2.9761</lower>
            <upper>2.9761</upper>
            <effort>9</effort>
            <velocity>3.485</velocity>
          </limit>
          <dynamics>
            <damping>1</damping>
            <friction>0.5</friction>
            <spring_reference>0</spring_reference>
            <spring_stiffness>0</spring_stiffness>
          </dynamics>
          <use_parent_model_frame>1</use_parent_model_frame>
        </axis>
        <physics>
          <provide_feedback>1</provide_feedback>
          <ode>
            <provide_feedback>1</provide_feedback>
            <implicit_spring_damper>1</implicit_spring_damper>
            <cfm_damping>1</cfm_damping>
            <limit>
              <cfm>0</cfm>
              <erp>0.2</erp>
            </limit>
          </ode>
        </physics>
      </joint>
      <link name='right_l6'>
        <pose frame=''>0.991 0.1603 0.317 1.57084 -1.39627 1.57075</pose>
        <inertial>
          <pose frame=''>-0.002956 0.008331 -0.004088 0 -0 0</pose>
          <mass>0.3392</mass>
          <inertia>
            <ixx>0.0103202</ixx>
            <ixy>-0.0100069</ixy>
            <ixz>-0.00997178</ixz>
            <iyy>0.010321</iyy>
            <iyz>0.009994</iyz>
            <izz>0.0104575</izz>
          </inertia>
        </inertial>
        <collision name='right_l6_collision'>
          <pose frame=''>0 0.015 -0.01 0 -0 0</pose>
          <geometry>
            <cylinder>
              <length>0.05</length>
              <radius>0.055</radius>
            </cylinder>
          </geometry>
          <max_contacts>10</max_contacts>
          <surface>
            <contact>
              <ode/>
            </contact>
            <bounce/>
            <friction>
              <torsional>
                <ode/>
              </torsional>
              <ode/>
            </friction>
          </surface>
        </collision>
        <collision name='right_l6_fixed_joint_lump__right_hand_collision_1'>
          <pose frame=''>0 0 0.0445 0 -0 1.5708</pose>
          <geometry>
            <cylinder>
              <length>0.03</length>
              <radius>0.035</radius>
            </cylinder>
          </geometry>
          <max_contacts>10</max_contacts>
          <surface>
            <contact>
              <ode/>
            </contact>
            <bounce/>
            <friction>
              <torsional>
                <ode/>
              </torsional>
              <ode/>
            </friction>
          </surface>
        </collision>
        <visual name='right_l6_visual'>
          <pose frame=''>0 0 0 0 -0 0</pose>
          <geometry>
            <mesh>
              <scale>1 1 1</scale>
              <uri>/home/user/ros_ws/src/sawyer_robot/sawyer_description/meshes/sawyer_mp1/l6.DAE</uri>
            </mesh>
          </geometry>
        </visual>
        <self_collide>0</self_collide>
        <kinematic>0</kinematic>
        <gravity>1</gravity>
      </link>
      <joint name='right_j6' type='revolute'>
        <child>right_l6</child>
        <parent>right_l5</parent>
        <axis>
          <xyz>1 0 -7e-06</xyz>
          <limit>
            <lower>-3.14</lower>
            <upper>3.14</upper>
            <effort>9</effort>
            <velocity>4.545</velocity>
          </limit>
          <dynamics>
            <damping>1</damping>
            <friction>0.5</friction>
            <spring_reference>0</spring_reference>
            <spring_stiffness>0</spring_stiffness>
          </dynamics>
          <use_parent_model_frame>1</use_parent_model_frame>
        </axis>
        <physics>
          <provide_feedback>1</provide_feedback>
          <ode>
            <provide_feedback>1</provide_feedback>
            <implicit_spring_damper>1</implicit_spring_damper>
            <cfm_damping>1</cfm_damping>
            <limit>
              <cfm>0</cfm>
              <erp>0.2</erp>
            </limit>
          </ode>
        </physics>
      </joint>
      <static>0</static>
      <plugin name='sawyer_ros_control' filename='libsawyer_gazebo_ros_control.so'>
        <robotNamespace>/robot</robotNamespace>
        <robotSimType>sawyer_gazebo/SawyerRobotHWSim</robotSimType>
        <controlPeriod>0.001</controlPeriod>
        <eStopTopic>sim_estop</eStopTopic>
      </plugin>
      <pose frame=''>0 0 0.93 0 -0 0</pose>
    </model>
    <model name='table'>
      <static>0</static>
      <link name='table::table::table::link'>
        <collision name='surface'>
          <pose frame=''>0 0 1 0 -0 0</pose>
          <geometry>
            <box>
              <size>1.5 0.8 0.03</size>
            </box>
          </geometry>
          <surface>
            <friction>
              <ode>
                <mu>0.6</mu>
                <mu2>0.6</mu2>
              </ode>
              <torsional>
                <ode/>
              </torsional>
            </friction>
            <contact>
              <ode/>
            </contact>
            <bounce/>
          </surface>
          <max_contacts>10</max_contacts>
        </collision>
        <visual name='visual1'>
          <pose frame=''>0 0 1 0 -0 0</pose>
          <geometry>
            <box>
              <size>1.4 0.8 0.04</size>
            </box>
          </geometry>
          <material>
            <script>
              <uri>file://media/materials/scripts/gazebo.material</uri>
              <name>Gazebo/Wood</name>
            </script>
          </material>
        </visual>
        <collision name='front_left_leg'>
          <pose frame=''>0.68 0.38 0.5 0 -0 0</pose>
          <geometry>
            <cylinder>
              <radius>0.02</radius>
              <length>1</length>
            </cylinder>
          </geometry>
          <max_contacts>10</max_contacts>
          <surface>
            <contact>
              <ode/>
            </contact>
            <bounce/>
            <friction>
              <torsional>
                <ode/>
              </torsional>
              <ode/>
            </friction>
          </surface>
        </collision>
        <visual name='front_left_leg'>
          <pose frame=''>0.68 0.38 0.5 0 -0 0</pose>
          <geometry>
            <cylinder>
              <radius>0.02</radius>
              <length>1</length>
            </cylinder>
          </geometry>
          <material>
            <script>
              <uri>file://media/materials/scripts/gazebo.material</uri>
              <name>Gazebo/Grey</name>
            </script>
          </material>
        </visual>
        <collision name='front_right_leg'>
          <pose frame=''>0.68 -0.38 0.5 0 -0 0</pose>
          <geometry>
            <cylinder>
              <radius>0.02</radius>
              <length>1</length>
            </cylinder>
          </geometry>
          <max_contacts>10</max_contacts>
          <surface>
            <contact>
              <ode/>
            </contact>
            <bounce/>
            <friction>
              <torsional>
                <ode/>
              </torsional>
              <ode/>
            </friction>
          </surface>
        </collision>
        <visual name='front_right_leg'>
          <pose frame=''>0.68 -0.38 0.5 0 -0 0</pose>
          <geometry>
            <cylinder>
              <radius>0.02</radius>
              <length>1</length>
            </cylinder>
          </geometry>
          <material>
            <script>
              <uri>file://media/materials/scripts/gazebo.material</uri>
              <name>Gazebo/Grey</name>
            </script>
          </material>
        </visual>
        <collision name='back_right_leg'>
          <pose frame=''>-0.68 -0.38 0.5 0 -0 0</pose>
          <geometry>
            <cylinder>
              <radius>0.02</radius>
              <length>1</length>
            </cylinder>
          </geometry>
          <max_contacts>10</max_contacts>
          <surface>
            <contact>
              <ode/>
            </contact>
            <bounce/>
            <friction>
              <torsional>
                <ode/>
              </torsional>
              <ode/>
            </friction>
          </surface>
        </collision>
        <visual name='back_right_leg'>
          <pose frame=''>-0.68 -0.38 0.5 0 -0 0</pose>
          <geometry>
            <cylinder>
              <radius>0.02</radius>
              <length>1</length>
            </cylinder>
          </geometry>
          <material>
            <script>
              <uri>file://media/materials/scripts/gazebo.material</uri>
              <name>Gazebo/Grey</name>
            </script>
          </material>
        </visual>
        <collision name='back_left_leg'>
          <pose frame=''>-0.68 0.38 0.5 0 -0 0</pose>
          <geometry>
            <cylinder>
              <radius>0.02</radius>
              <length>1</length>
            </cylinder>
          </geometry>
          <max_contacts>10</max_contacts>
          <surface>
            <contact>
              <ode/>
            </contact>
            <bounce/>
            <friction>
              <torsional>
                <ode/>
              </torsional>
              <ode/>
            </friction>
          </surface>
        </collision>
        <visual name='back_left_leg'>
          <pose frame=''>-0.68 0.38 0.5 0 -0 0</pose>
          <geometry>
            <cylinder>
              <radius>0.02</radius>
              <length>1</length>
            </cylinder>
          </geometry>
          <material>
            <script>
              <uri>file://media/materials/scripts/gazebo.material</uri>
              <name>Gazebo/Grey</name>
            </script>
          </material>
        </visual>
        <self_collide>0</self_collide>
        <inertial>
          <inertia>
            <ixx>1</ixx>
            <ixy>0</ixy>
            <ixz>0</ixz>
            <iyy>1</iyy>
            <iyz>0</iyz>
            <izz>1</izz>
          </inertia>
          <mass>1</mass>
        </inertial>
        <kinematic>1</kinematic>
        <gravity>0</gravity>
      </link>
      <pose frame=''>-0.02777 -0.897424 0 0 -0 0</pose>
    </model>
    <state world_name='default'>
      <sim_time>237 342000000</sim_time>
      <real_time>379 399744691</real_time>
      <wall_time>1543461421 426521197</wall_time>
      <iterations>237342</iterations>
      <model name='ground_plane'>
        <pose frame=''>0 0 0 0 -0 0</pose>
        <scale>1 1 1</scale>
        <link name='link'>
          <pose frame=''>0 0 0 0 -0 0</pose>
          <velocity>0 0 0 0 -0 0</velocity>
          <acceleration>0 0 0 0 -0 0</acceleration>
          <wrench>0 0 0 0 -0 0</wrench>
        </link>
      </model>
      <model name='sawyer'>
        <pose frame=''>0 0 0.93 0 -0 0</pose>
        <scale>1 1 1</scale>
        <link name='base'>
          <pose frame=''>0 0 0.93 0 -0 0</pose>
          <velocity>1e-06 -6e-06 0 3e-06 -0 -1e-06</velocity>
          <acceleration>0.002521 -0.008675 -0.000312 0.006143 0.000365 -0.002469</acceleration>
          <wrench>0.158673 -0.545922 -0.019616 0 -0 0</wrench>
        </link>
        <link name='head'>
          <pose frame=''>0 0 1.3065 -1e-06 -0 -0.261041</pose>
          <velocity>4.2e-05 0.000392 1.4e-05 -0.00142 0.000291 -0.024807</velocity>
          <acceleration>0.073346 0.81973 0.028659 -2.87915 0.247124 0.651903</acceleration>
          <wrench>0.11585 1.29476 0.045267 0 -0 0</wrench>
        </link>
        <link name='right_l0'>
          <pose frame=''>0 0 1.01 1e-06 -0 -0.261296</pose>
          <velocity>2.6e-05 0.000257 -1.2e-05 0.000363 -9.8e-05 0.001772</velocity>
          <acceleration>0.008488 0.502535 -0.015727 2.36135 -1.42257 -0.883506</acceleration>
          <wrench>0.045166 2.67414 -0.083688 0 -0 0</wrench>
        </link>
        <link name='right_l1'>
          <pose frame=''>0.091167 0.027378 1.247 1.57079 0.074411 2.8803</pose>
          <velocity>-0.000152 0.000214 -0.000387 0.008638 0.032047 0.002672</velocity>
          <acceleration>-2.47376 1.03933 -1.09799 0.304265 0.358221 0.993111</acceleration>
          <wrench>-11.1443 4.6822 -4.94643 0 -0 0</wrench>
        </link>
        <link name='right_l2'>
          <pose frame=''>0.138035 0.162352 1.10739 3.12931 0.073392 2.71434</pose>
          <velocity>-0.005149 0.001069 -0.0007 -0.019085 0.040002 0.35151</velocity>
          <acceleration>-9.68879 -0.4309 -1.0745 2.01782 0.53287 2.49046</acceleration>
          <wrench>-16.9069 -0.75192 -1.87501 0 -0 0</wrench>
        </link>
        <link name='right_l3'>
          <pose frame=''>0.139341 0.11912 0.847592 1.55845 0.122163 2.71373</pose>
          <velocity>-0.000489 -0.003658 0.000535 0.113402 0.334385 0.356105</velocity>
          <acceleration>36.8387 -20.258 1.17849 -1.23549 0.38841 0.519678</acceleration>
          <wrench>92.454 -50.8415 2.95766 0 -0 0</wrench>
        </link>
        <link name='right_l4'>
          <pose frame=''>0.101529 -0.000964 0.721984 3.13359 0.12252 2.74925</pose>
          <velocity>4.4e-05 -0.003216 -0.000408 0.238482 0.292976 -0.735475</velocity>
          <acceleration>-77.1581 27.6192 -12.299 -0.693003 0.45109 -0.500625</acceleration>
          <wrench>-85.9232 30.7567 -13.6961 0 -0 0</wrench>
        </link>
        <link name='right_l5'>
          <pose frame=''>0.145251 0.016874 0.4493 1.56259 0.251713 2.74819</pose>
          <velocity>-0.066884 0.029511 -0.009056 -0.136524 -0.614062 -0.742903</velocity>
          <acceleration>0.768999 9.11157 -1.58274 1.8027 -1.31111 0.373152</acceleration>
          <wrench>1.20156 14.2368 -2.47303 0 -0 0</wrench>
        </link>
        <link name='right_l6'>
          <pose frame=''>0.211066 0.104541 0.343607 3.11056 -0.249963 -0.235637</pose>
          <velocity>0.063128 -0.033857 0.019359 -0.535542 -0.463983 0.914397</velocity>
          <acceleration>135.928 -74.4931 40.9423 -0.204468 -0.219878 2.27954</acceleration>
          <wrench>46.1069 -25.268 13.8876 0 -0 0</wrench>
        </link>
      </model>
      <model name='table'>
        <pose frame=''>0.780384 0.026325 -0.311602 -0.003003 -0.011713 1.57646</pose>
        <scale>1 1 1</scale>
        <link name='table::table::table::link'>
          <pose frame=''>0.780384 0.026325 -0.311602 -0.003003 -0.011713 1.57646</pose>
          <velocity>0 0 0 0 -0 0</velocity>
          <acceleration>0 0 0 0 -0 0</acceleration>
          <wrench>0 0 0 0 -0 0</wrench>
        </link>
      </model>
      <light name='sun'>
        <pose frame=''>0 0 10 0 -0 0</pose>
      </light>
    </state>
  </world>
</sdf>
